Workbook

Sheet Sheet1
A1: 碎片类型 | B1: 独立id | C1: 英雄类型 | D1: 元素 | E1: 权重 | F1: 碎片名称 | G1: 英雄名称 | H1: 英雄星级 | I1: 英雄梯度 | J1: 英雄是否产出 | K1: 英雄梯度
A2: 3 | B2: 3 | C2: 3 | D2: 3 | E2: 3 | F2: 3 | G2: 3 | H2: 3 | I2: 3 | J2: 3 | K2: 3
A3: item_type | B3: idx | C3: hero_id | D3: element | E3: weight | F3: note1 | G3: note2 | H3: note3 | I3: note4 | J3: note5 | K3: note5
A4: 950001 | B4: 1 | C4: 10105007 | D4: 1 | E4: 50 | F4: 火系精英碎片 | G4: 烈焰骑士 | H4: 5 | I4: 1 | J4: =IFERROR(INDEX(Sheet2!$J$2:$J$11,MATCH(G4,Sheet2!$H$2:$H$11,0)),"无") -> 无 | K4: =IFERROR(INDEX(Sheet2!$I$14:$I$30,MATCH(G4,Sheet2!$H$14:$H$30,0)),"无") -> 1
A5: 950001 | B5: 2 | C5: 10105008 | D5: 1 | E5: 50 | F5: 火系精英碎片 | G5: 毁灭之烬 | H5: 5 | I5: 1 | J5: =IFERROR(INDEX(Sheet2!$J$2:$J$11,MATCH(G5,Sheet2!$H$2:$H$11,0)),"无") -> 无 | K5: =IFERROR(INDEX(Sheet2!$I$14:$I$30,MATCH(G5,Sheet2!$H$14:$H$30,0)),"无") -> 1
A6: 950001 | B6: 3 | C6: 10105009 | D6: 1 | E6: 800 | F6: 火系精英碎片 | G6: 赤焰舞姬 | H6: 5 | I6: 2 | J6: =IFERROR(INDEX(Sheet2!$J$2:$J$11,MATCH(G6,Sheet2!$H$2:$H$11,0)),"无") -> 无 | K6: =IFERROR(INDEX(Sheet2!$I$14:$I$30,MATCH(G6,Sheet2!$H$14:$H$30,0)),"无") -> 无
A7: 950001 | B7: 4 | C7: 10105013 | D7: 1 | E7: 800 | F7: 火系精英碎片 | G7: 恶灵少女·莉莉安 | H7: 5 | I7: 2 | J7: =IFERROR(INDEX(Sheet2!$J$2:$J$11,MATCH(G7,Sheet2!$H$2:$H$11,0)),"无") -> 无 | K7: =IFERROR(INDEX(Sheet2!$I$14:$I$30,MATCH(G7,Sheet2!$H$14:$H$30,0)),"无") -> 无
A8: 950001 | B8: 5 | C8: 10105014 | D8: 1 | E8: 800 | F8: 火系精英碎片 | G8: 沐火龙姬 | H8: 5 | I8: 2 | J8: =IFERROR(INDEX(Sheet2!$J$2:$J$11,MATCH(G8,Sheet2!$H$2:$H$11,0)),"无") -> 无 | K8: =IFERROR(INDEX(Sheet2!$I$14:$I$30,MATCH(G8,Sheet2!$H$14:$H$30,0)),"无") -> 无
A9: 950001 | B9: 6 | C9: 10105015 | D9: 1 | E9: 500 | F9: 火系精英碎片 | G9: 时间魔女·金妮 | H9: 5 | I9: 2 | J9: =IFERROR(INDEX(Sheet2!$J$2:$J$11,MATCH(G9,Sheet2!$H$2:$H$11,0)),"无") -> 无 | K9: =IFERROR(INDEX(Sheet2!$I$14:$I$30,MATCH(G9,Sheet2!$H$14:$H$30,0)),"无") -> 无
A10: 950001 | B10: 7 | C10: 10105020 | D10: 1 | E10: 50 | F10: 火系精英碎片 | G10: 尼罗公主 | H10: 5 | I10: 1 | J10: =IFERROR(INDEX(Sheet2!$J$2:$J$11,MATCH(G10,Sheet2!$H$2:$H$11,0)),"无") -> 无 | K10: =IFERROR(INDEX(Sheet2!$I$14:$I$30,MATCH(G10,Sheet2!$H$14:$H$30,0)),"无") -> 1
A11: 950001 | B11: 8 | C11: 10105022 | D11: 1 | E11: 0 | F11: 火系精英碎片 | G11: 圣焰女巫·迦娜 | H11: 5 | I11: 1 | J11: =IFERROR(INDEX(Sheet2!$J$2:$J$11,MATCH(G11,Sheet2!$H$2:$H$11,0)),"无") -> 1 | K11: =IFERROR(INDEX(Sheet2!$I$14:$I$30,MATCH(G11,Sheet2!$H$14:$H$30,0)),"无") -> 无
A12: 950002 | B12: 9 | C12: 10205008 | D12: 2 | E12: 800 | F12: 水系精英碎片 | G12: 格伦男爵 | H12: 5 | I12: 2 | J12: =IFERROR(INDEX(Sheet2!$J$2:$J$11,MATCH(G12,Sheet2!$H$2:$H$11,0)),"无") -> 无 | K12: =IFERROR(INDEX(Sheet2!$I$14:$I$30,MATCH(G12,Sheet2!$H$14:$H$30,0)),"无") -> 无
A13: 950002 | B13: 10 | C13: 10205009 | D13: 2 | E13: 100 | F13: 水系精英碎片 | G13: 亚瑟 | H13: 5 | I13: 1 | J13: =IFERROR(INDEX(Sheet2!$J$2:$J$11,MATCH(G13,Sheet2!$H$2:$H$11,0)),"无") -> 无 | K13: =IFERROR(INDEX(Sheet2!$I$14:$I$30,MATCH(G13,Sheet2!$H$14:$H$30,0)),"无") -> 无
A14: 950002 | B14: 11 | C14: 10205010 | D14: 2 | E14: 100 | F14: 水系精英碎片 | G14: 时光刺客 | H14: 5 | I14: 1 | J14: =IFERROR(INDEX(Sheet2!$J$2:$J$11,MATCH(G14,Sheet2!$H$2:$H$11,0)),"无") -> 无 | K14: =IFERROR(INDEX(Sheet2!$I$14:$I$30,MATCH(G14,Sheet2!$H$14:$H$30,0)),"无") -> 无
A15: 950002 | B15: 12 | C15: 10205011 | D15: 2 | E15: 800 | F15: 水系精英碎片 | G15: 章鱼公主 | H15: 5 | I15: 2 | J15: =IFERROR(INDEX(Sheet2!$J$2:$J$11,MATCH(G15,Sheet2!$H$2:$H$11,0)),"无") -> 无 | K15: =IFERROR(INDEX(Sheet2!$I$14:$I$30,MATCH(G15,Sheet2!$H$14:$H$30,0)),"无") -> 无
... A317: 20105022 | B317: 314 | C317: 10105022 | D317: 1 | E317: 1000 | F317: 圣焰女巫·迦娜碎片 | G317: 圣焰女巫·迦娜 | H317: 5 | I317: 1 | J317: =IFERROR(INDEX(Sheet2!$J$2:$J$11,MATCH(G317,Sheet2!$H$2:$H$11,0)),"无") -> 1 | K317: =IFERROR(INDEX(Sheet2!$I$14:$I$30,MATCH(G317,Sheet2!$H$14:$H$30,0)),"无") -> 无
A318: 20105023 | B318: 392 | C318: 10105023 | D318: 1 | E318: 1000 | F318: 火灵领主·阿塔卡碎片 | G318: 火灵领主·阿塔卡 | H318: 5 | I318: 1 | J318: 1 | K318: 1
A319: 20201001 | B319: 315 | C319: 10201001 | D319: 2 | E319: 1000 | F319: 布鲁碎片 | G319: 布鲁 | H319: 1 | I319: 999 | J319: =IFERROR(INDEX(Sheet2!$J$2:$J$11,MATCH(G319,Sheet2!$H$2:$H$11,0)),"无") -> 无 | K319: =IFERROR(INDEX(Sheet2!$I$14:$I$30,MATCH(G319,Sheet2!$H$14:$H$30,0)),"无") -> 无
A320: 20202002 | B320: 316 | C320: 10202002 | D320: 2 | E320: 1000 | F320: 冰霜元素碎片 | G320: 冰霜元素 | H320: 2 | I320: 999 | J320: =IFERROR(INDEX(Sheet2!$J$2:$J$11,MATCH(G320,Sheet2!$H$2:$H$11,0)),"无") -> 无 | K320: =IFERROR(INDEX(Sheet2!$I$14:$I$30,MATCH(G320,Sheet2!$H$14:$H$30,0)),"无") -> 无
A321: 20203003 | B321: 317 | C321: 10203003 | D321: 2 | E321: 1000 | F321: 冰晶女巫碎片 | G321: 冰晶女巫 | H321: 3 | I321: 999 | J321: =IFERROR(INDEX(Sheet2!$J$2:$J$11,MATCH(G321,Sheet2!$H$2:$H$11,0)),"无") -> 无 | K321: =IFERROR(INDEX(Sheet2!$I$14:$I$30,MATCH(G321,Sheet2!$H$14:$H$30,0)),"无") -> 无
A322: 20204004 | B322: 318 | C322: 10204004 | D322: 2 | E322: 1000 | F322: 缇芮碎片 | G322: 缇芮 | H322: 4 | I322: 999 | J322: =IFERROR(INDEX(Sheet2!$J$2:$J$11,MATCH(G322,Sheet2!$H$2:$H$11,0)),"无") -> 无 | K322: =IFERROR(INDEX(Sheet2!$I$14:$I$30,MATCH(G322,Sheet2!$H$14:$H$30,0)),"无") -> 无
A323: 20204005 | B323: 319 | C323: 10204005 | D323: 2 | E323: 1000 | F323: 寒冬之怒碎片 | G323: 寒冬之怒 | H323: 4 | I323: 999 | J323: =IFERROR(INDEX(Sheet2!$J$2:$J$11,MATCH(G323,Sheet2!$H$2:$H$11,0)),"无") -> 无 | K323: =IFERROR(INDEX(Sheet2!$I$14:$I$30,MATCH(G323,Sheet2!$H$14:$H$30,0)),"无") -> 无
A324: 20205006 | B324: 320 | C324: 10205006 | D324: 2 | E324: 1000 | F324: 海神祭司碎片 | G324: 海神祭司 | H324: 5 | I324: 3 | J324: =IFERROR(INDEX(Sheet2!$J$2:$J$11,MATCH(G324,Sheet2!$H$2:$H$11,0)),"无") -> 无 | K324: =IFERROR(INDEX(Sheet2!$I$14:$I$30,MATCH(G324,Sheet2!$H$14:$H$30,0)),"无") -> 无
A325: 20205007 | B325: 321 | C325: 10205007 | D325: 2 | E325: 1000 | F325: 寒冰战姬碎片 | G325: 寒冰战姬 | H325: 5 | I325: 3 | J325: =IFERROR(INDEX(Sheet2!$J$2:$J$11,MATCH(G325,Sheet2!$H$2:$H$11,0)),"无") -> 无 | K325: =IFERROR(INDEX(Sheet2!$I$14:$I$30,MATCH(G325,Sheet2!$H$14:$H$30,0)),"无") -> 无
A326: 20205008 | B326: 322 | C326: 10205008 | D326: 2 | E326: 1000 | F326: 格伦男爵碎片 | G326: 格伦男爵 | H326: 5 | I326: 2 | J326: =IFERROR(INDEX(Sheet2!$J$2:$J$11,MATCH(G326,Sheet2!$H$2:$H$11,0)),"无") -> 无 | K326: =IFERROR(INDEX(Sheet2!$I$14:$I$30,MATCH(G326,Sheet2!$H$14:$H$30,0)),"无") -> 无
A327: 20205009 | B327: 323 | C327: 10205009 | D327: 2 | E327: 1000 | F327: 亚瑟碎片 | G327: 亚瑟 | H327: 5 | I327: 1 | J327: =IFERROR(INDEX(Sheet2!$J$2:$J$11,MATCH(G327,Sheet2!$H$2:$H$11,0)),"无") -> 无 | K327: =IFERROR(INDEX(Sheet2!$I$14:$I$30,MATCH(G327,Sheet2!$H$14:$H$30,0)),"无") -> 无
A328: 20205010 | B328: 324 | C328: 10205010 | D328: 2 | E328: 1000 | F328: 时光刺客碎片 | G328: 时光刺客 | H328: 5 | I328: 1 | J328: =IFERROR(INDEX(Sheet2!$J$2:$J$11,MATCH(G328,Sheet2!$H$2:$H$11,0)),"无") -> 无 | K328: =IFERROR(INDEX(Sheet2!$I$14:$I$30,MATCH(G328,Sheet2!$H$14:$H$30,0)),"无") -> 无
A329: 20205011 | B329: 325 | C329: 10205011 | D329: 2 | E329: 1000 | F329: 章鱼公主碎片 | G329: 章鱼公主 | H329: 5 | I329: 2 | J329: =IFERROR(INDEX(Sheet2!$J$2:$J$11,MATCH(G329,Sheet2!$H$2:$H$11,0)),"无") -> 无 | K329: =IFERROR(INDEX(Sheet2!$I$14:$I$30,MATCH(G329,Sheet2!$H$14:$H$30,0)),"无") -> 无
A330: 20204012 | B330: 326 | C330: 10204012 | D330: 2 | E330: 1000 | F330: 冰脊龙碎片 | G330: 恶龙之眼 | H330: 4 | I330: 999 | J330: =IFERROR(INDEX(Sheet2!$J$2:$J$11,MATCH(G330,Sheet2!$H$2:$H$11,0)),"无") -> 无 | K330: =IFERROR(INDEX(Sheet2!$I$14:$I$30,MATCH(G330,Sheet2!$H$14:$H$30,0)),"无") -> 无
... A378: 20405015 | B378: 373 | C378: 10405015 | D378: 4 | E378: 1000 | F378: 起源法则·创世碎片 | G378: 起源法则·创世 | H378: 5 | I378: 1 | J378: =IFERROR(INDEX(Sheet2!$J$2:$J$11,MATCH(G378,Sheet2!$H$2:$H$11,0)),"无") -> 1 | K378: =IFERROR(INDEX(Sheet2!$I$14:$I$30,MATCH(G378,Sheet2!$H$14:$H$30,0)),"无") -> 无
A379: 20405016 | B379: 374 | C379: 10405016 | D379: 4 | E379: 1000 | F379: 魔法少女·樱碎片 | G379: 魔法少女·樱 | H379: 5 | I379: 1 | J379: 无 | K379: 无
A380: 20405017 | B380: 393 | C380: 10405017 | D380: 4 | E380: 1000 | F380: 光之幻·月碎片 | G380: 光之幻·月 | H380: 5 | I380: 1 | J380: 1 | K380: 1
A381: 20405018 | B381: 395 | C381: 10405018 | D381: 4 | E381: 1000 | F381: 圣龙王座-欧西里斯碎片 | G381: 圣龙王座-欧西里斯 | H381: 5 | I381: 1 | J381: 1 | K381: 1
A382: 20405019 | B382: 398 | C382: 10405019 | D382: 4 | E382: 1000 | F382: 奶牛特工·慕思碎片 | G382: 奶牛特工·慕思 | H382: 5 | I382: 1 | J382: 1 | K382: 1
A383: 20405020 | B383: 401 | C383: 10405020 | D383: 4 | E383: 1000 | F383: 异瞳猫女·朵拉碎片 | G383: 异瞳猫女·朵拉 | H383: 5 | I383: 1 | J383: 1 | K383: 1
A384: 20503001 | B384: 375 | C384: 10503001 | D384: 5 | E384: 1000 | F384: 恶魔之眼碎片 | G384: 恶魔之眼 | H384: 3 | I384: 999 | J384: =IFERROR(INDEX(Sheet2!$J$2:$J$11,MATCH(G384,Sheet2!$H$2:$H$11,0)),"无") -> 无 | K384: =IFERROR(INDEX(Sheet2!$I$14:$I$30,MATCH(G384,Sheet2!$H$14:$H$30,0)),"无") -> 无
A385: 20504002 | B385: 376 | C385: 10504002 | D385: 5 | E385: 1000 | F385: 深渊元首碎片 | G385: 深渊元首 | H385: 4 | I385: 999 | J385: =IFERROR(INDEX(Sheet2!$J$2:$J$11,MATCH(G385,Sheet2!$H$2:$H$11,0)),"无") -> 无 | K385: =IFERROR(INDEX(Sheet2!$I$14:$I$30,MATCH(G385,Sheet2!$H$14:$H$30,0)),"无") -> 无
A386: 20504003 | B386: 377 | C386: 10504003 | D386: 5 | E386: 1000 | F386: 暗黑女爵碎片 | G386: 暗黑女爵 | H386: 5 | I386: 3 | J386: =IFERROR(INDEX(Sheet2!$J$2:$J$11,MATCH(G386,Sheet2!$H$2:$H$11,0)),"无") -> 无 | K386: =IFERROR(INDEX(Sheet2!$I$14:$I$30,MATCH(G386,Sheet2!$H$14:$H$30,0)),"无") -> 无
A387: 20505004 | B387: 378 | C387: 10505004 | D387: 5 | E387: 1000 | F387: 爱德华碎片 | G387: 爱德华 | H387: 5 | I387: 2 | J387: =IFERROR(INDEX(Sheet2!$J$2:$J$11,MATCH(G387,Sheet2!$H$2:$H$11,0)),"无") -> 无 | K387: =IFERROR(INDEX(Sheet2!$I$14:$I$30,MATCH(G387,Sheet2!$H$14:$H$30,0)),"无") -> 无
A388: 20505005 | B388: 379 | C388: 10505005 | D388: 5 | E388: 1000 | F388: 黑暗切割者碎片 | G388: 黑暗切割者 | H388: 5 | I388: 1 | J388: =IFERROR(INDEX(Sheet2!$J$2:$J$11,MATCH(G388,Sheet2!$H$2:$H$11,0)),"无") -> 无 | K388: =IFERROR(INDEX(Sheet2!$I$14:$I$30,MATCH(G388,Sheet2!$H$14:$H$30,0)),"无") -> 1
...

Sheet Sheet2
A1: 类型 | D1: 职业 | E1: 元素 | F1: 初始星级
A2: 10101001 | B2: 独眼梦魇 | C2: #N/A | D2: 1 | E2: 1 | F2: 1 | H2: 乃音 | I2: 高抽没产出 | J2: 1
A3: 10102002 | B3: 玛蒙 | C3: #N/A | D3: 4 | E3: 1 | F3: 2 | H3: 祷告少女·樱乃 | I3: 高抽没产出 | J3: 1
A4: 10103003 | B4: 灰烬使者 | C4: #N/A | D4: 1 | E4: 1 | F4: 3 | H4: 圣焰女巫·迦娜 | I4: 高抽没产出 | J4: 1
A5: 10104004 | B5: 赛西莉 | C5: #N/A | D5: 3 | E5: 1 | F5: 4 | H5: 凯萨丁 | I5: 高抽没产出 | J5: 1
A6: 10104005 | B6: 荆棘之炎 | C6: #N/A | D6: 4 | E6: 1 | F6: 4 | H6: 圣光精灵 | I6: 高抽没产出 | J6: 1
A7: 10105006 | B7: 安妮雅 | C7: 3 | D7: 3 | E7: 1 | F7: 5 | H7: 兔兔大小姐 | I7: 高抽没产出 | J7: 1
A8: 10105007 | B8: 烈焰骑士 | C8: 1 | D8: 3 | E8: 1 | F8: 5 | H8: 起源法则·创世 | I8: 高抽没产出 | J8: 1
A9: 10105008 | B9: 毁灭之烬 | C9: 1 | D9: 1 | E9: 1 | F9: 5 | H9: 冥灯女王 | I9: 高抽没产出 | J9: 1
A10: 10105009 | B10: 赤焰舞姬 | C10: 2 | D10: 1 | E10: 1 | F10: 5 | H10: 暗影驱动·卡卡 | I10: 高抽没产出 | J10: 1
A11: 10105010 | B11: 琪亚娜 | C11: 3 | D11: 2 | E11: 1 | F11: 5 | H11: 无双假面*晓 | I11: 已产出 | J11: 1
A12: 10105011 | B12: 魅惑之拥 | C12: 3 | D12: 5 | E12: 1 | F12: 5
A13: 10104012 | B13: 武道女帝·弥岚 | C13: #N/A | D13: 2 | E13: 1 | F13: 4
A14: 10105013 | B14: 恶灵少女·莉莉安 | C14: 2 | D14: 4 | E14: 1 | F14: 5 | H14: 主宰者 | I14: 1
A15: 10105014 | B15: 沐火龙姬 | C15: 2 | D15: 2 | E15: 1 | F15: 5 | H15: 圣殿骑士 | I15: 1
A16: 10105015 | B16: 时间魔女·金妮 | C16: 2 | D16: 2 | E16: 1 | F16: 5 | H16: 始祖夏姆达 | I16: 1
A17: 10104016 | B17: 肥啾 | C17: #N/A | D17: 1 | E17: 1 | F17: 4 | H17: 黑暗切割者 | I17: 1
A18: 10104017 | B18: 炽焰幼龙 | C18: #N/A | D18: 1 | E18: 1 | F18: 4 | H18: 缚魂者·零 | I18: 1
A19: 10105018 | B19: 莫迪诺加斯 | C19: 3 | D19: 1 | E19: 1 | F19: 5 | H19: 黑暗兵器·阿金妮 | I19: 1
A20: 10105019 | B20: 凯兹 | C20: 3 | D20: 2 | E20: 1 | F20: 5 | H20: 超载者·W | I20: 1
A21: 10105020 | B21: 尼罗公主 | C21: 1 | D21: 2 | E21: 1 | F21: 5 | H21: 森林缴械者 | I21: 1
A22: 10105022 | B22: 圣焰女巫·迦娜 | C22: 1 | D22: 5 | E22: 1 | F22: 5 | H22: 萝莫拉 | I22: 1
A23: 10201001 | B23: 布鲁 | C23: #N/A | D23: 5 | E23: 2 | F23: 1 | H23: 森林之主 | I23: 1
A24: 10202002 | B24: 冰霜元素 | C24: #N/A | D24: 1 | E24: 2 | F24: 2 | H24: 冰晶骑士 | I24: 1
A25: 10203003 | B25: 冰晶女巫 | C25: #N/A | D25: 3 | E25: 2 | F25: 3 | H25: 占星师·喵莉丝 | I25: 1
A26: 10204004 | B26: 缇芮 | C26: #N/A | D26: 1 | E26: 2 | F26: 4 | H26: 露希安 | I26: 1
A27: 10204005 | B27: 寒冬之怒 | C27: #N/A | D27: 2 | E27: 2 | F27: 4 | H27: 烈焰骑士 | I27: 1
A28: 10205006 | B28: 海神祭司 | C28: 3 | D28: 1 | E28: 2 | F28: 5 | H28: 毁灭之烬 | I28: 1
A29: 10205007 | B29: 寒冰战姬 | C29: 3 | D29: 4 | E29: 2 | F29: 5 | H29: 尼罗公主 | I29: 1
A30: 10205008 | B30: 格伦男爵 | C30: 2 | D30: 3 | E30: 2 | F30: 5 | H30: 无双假面*晓 | I30: 1
A31: 10205009 | B31: 亚瑟 | C31: 1 | D31: 1 | E31: 2 | F31: 5
A32: 10205010 | B32: 时光刺客 | C32: 1 | D32: 4 | E32: 2 | F32: 5
A33: 10205011 | B33: 章鱼公主 | C33: 2 | D33: 2 | E33: 2 | F33: 5
A34: 10204012 | B34: 恶龙之眼 | C34: #N/A | D34: 1 | E34: 2 | F34: 4
A35: 10204013 | B35: 唤潮剑姬 | C35: 3 | D35: 1 | E35: 2 | F35: 5
A36: 10205014 | B36: 乃音 | C36: 1 | D36: 3 | E36: 2 | F36: 5
A37: 10205015 | B37: 凯萨丁 | C37: 2 | D37: 5 | E37: 2 | F37: 5
A38: 10204016 | B38: Doc.企鹅绅士 | C38: #N/A | D38: 1 | E38: 2 | F38: 4
A39: 10204017 | B39: 水元素史莱姆 | C39: #N/A | D39: 1 | E39: 2 | F39: 4
A40: 10205018 | B40: 诺薇亚之心 | C40: 3 | D40: 1 | E40: 2 | F40: 5
...

Sheet Sheet3
A1: 950001 | B1: 火系精英碎片
A2: 950002 | B2: 水系精英碎片
A3: 950003 | B3: 木系精英碎片
A4: 950004 | B4: 光系精英碎片
A5: 950005 | B5: 暗系精英碎片
A6: 950006 | B6: 5星精英碎片
A7: 950007 | B7: 光暗精英碎片
A8: 950008 | B8: 普通光暗5星碎片
A9: 20003000 | B9: 随机3星碎片
A10: 20103000 | B10: 火系3星碎片
A11: 20203000 | B11: 水系3星碎片
A12: 20303000 | B12: 木系3星碎片
... A119: 20505014 | B119: 冥灯女王碎片
